[2024-12-02T00:00:03.508+0000] {local_task_job_runner.py:123} INFO - ::group::Pre task execution logs
[2024-12-02T00:00:03.523+0000] {taskinstance.py:2613} INFO - Dependencies all met for dep_context=non-requeueable deps ti=<TaskInstance: s3_dag.upload_to_s3 scheduled__2024-12-01T00:00:00+00:00 [queued]>
[2024-12-02T00:00:03.531+0000] {taskinstance.py:2613} INFO - Dependencies all met for dep_context=requeueable deps ti=<TaskInstance: s3_dag.upload_to_s3 scheduled__2024-12-01T00:00:00+00:00 [queued]>
[2024-12-02T00:00:03.532+0000] {taskinstance.py:2866} INFO - Starting attempt 1 of 1
[2024-12-02T00:00:03.547+0000] {taskinstance.py:2889} INFO - Executing <Task(PythonOperator): upload_to_s3> on 2024-12-01 00:00:00+00:00
[2024-12-02T00:00:03.552+0000] {warnings.py:112} WARNING - /home/***/.local/lib/python3.12/site-packages/***/task/task_runner/standard_task_runner.py:70: DeprecationWarning: This process (pid=9895) is multi-threaded, use of fork() may lead to deadlocks in the child.
  pid = os.fork()

[2024-12-02T00:00:03.554+0000] {standard_task_runner.py:72} INFO - Started process 9897 to run task
[2024-12-02T00:00:03.555+0000] {standard_task_runner.py:104} INFO - Running: ['***', 'tasks', 'run', 's3_dag', 'upload_to_s3', 'scheduled__2024-12-01T00:00:00+00:00', '--job-id', '200', '--raw', '--subdir', 'DAGS_FOLDER/s3_upload.py', '--cfg-path', '/tmp/tmpui7wrcro']
[2024-12-02T00:00:03.556+0000] {standard_task_runner.py:105} INFO - Job 200: Subtask upload_to_s3
[2024-12-02T00:00:03.603+0000] {task_command.py:467} INFO - Running <TaskInstance: s3_dag.upload_to_s3 scheduled__2024-12-01T00:00:00+00:00 [running]> on host 4b3a7f9b2751
[2024-12-02T00:00:03.685+0000] {taskinstance.py:3132} INFO - Exporting env vars: AIRFLOW_CTX_DAG_OWNER='***' AIRFLOW_CTX_DAG_ID='s3_dag' AIRFLOW_CTX_TASK_ID='upload_to_s3' AIRFLOW_CTX_EXECUTION_DATE='2024-12-01T00:00:00+00:00' AIRFLOW_CTX_TRY_NUMBER='1' AIRFLOW_CTX_DAG_RUN_ID='scheduled__2024-12-01T00:00:00+00:00'
[2024-12-02T00:00:03.686+0000] {logging_mixin.py:190} INFO - Task instance is in running state
[2024-12-02T00:00:03.686+0000] {logging_mixin.py:190} INFO -  Previous state of the Task instance: queued
[2024-12-02T00:00:03.687+0000] {logging_mixin.py:190} INFO - Current task name:upload_to_s3 state:running start_date:2024-12-02 00:00:03.524470+00:00
[2024-12-02T00:00:03.688+0000] {logging_mixin.py:190} INFO - Dag name:s3_dag and current dag run status:running
[2024-12-02T00:00:03.688+0000] {taskinstance.py:731} INFO - ::endgroup::
[2024-12-02T00:00:03.697+0000] {base.py:84} INFO - Retrieving connection 's3_conn'
[2024-12-02T00:00:03.698+0000] {connection_wrapper.py:325} INFO - AWS Connection (conn_id='s3_conn', conn_type='aws') credentials retrieved from login and password.
[2024-12-02T00:00:04.573+0000] {taskinstance.py:3311} ERROR - Task failed with exception
Traceback (most recent call last):
  File "/home/airflow/.local/lib/python3.12/site-packages/airflow/models/taskinstance.py", line 767, in _execute_task
    result = _execute_callable(context=context, **execute_callable_kwargs)
             ^^^^^^^^^^^^^^^^^^^^^^^^^^^^^^^^^^^^^^^^^^^^^^^^^^^^^^^^^^^^^
  File "/home/airflow/.local/lib/python3.12/site-packages/airflow/models/taskinstance.py", line 733, in _execute_callable
    return ExecutionCallableRunner(
           ^^^^^^^^^^^^^^^^^^^^^^^^
  File "/home/airflow/.local/lib/python3.12/site-packages/airflow/utils/operator_helpers.py", line 252, in run
    return self.func(*args, **kwargs)
           ^^^^^^^^^^^^^^^^^^^^^^^^^^
  File "/home/airflow/.local/lib/python3.12/site-packages/airflow/models/baseoperator.py", line 417, in wrapper
    return func(self, *args, **kwargs)
           ^^^^^^^^^^^^^^^^^^^^^^^^^^^
  File "/home/airflow/.local/lib/python3.12/site-packages/airflow/operators/python.py", line 238, in execute
    return_value = self.execute_callable()
                   ^^^^^^^^^^^^^^^^^^^^^^^
  File "/home/airflow/.local/lib/python3.12/site-packages/airflow/operators/python.py", line 256, in execute_callable
    return runner.run(*self.op_args, **self.op_kwargs)
           ^^^^^^^^^^^^^^^^^^^^^^^^^^^^^^^^^^^^^^^^^^^
  File "/home/airflow/.local/lib/python3.12/site-packages/airflow/utils/operator_helpers.py", line 252, in run
    return self.func(*args, **kwargs)
           ^^^^^^^^^^^^^^^^^^^^^^^^^^
  File "/opt/airflow/dags/s3_upload.py", line 11, in upload_to_s3
    hook.load_file(filename=filename, key=key, bucket_name=bucket_name)
  File "/home/airflow/.local/lib/python3.12/site-packages/airflow/providers/amazon/aws/hooks/s3.py", line 155, in wrapper
    return func(*bound_args.args, **bound_args.kwargs)
           ^^^^^^^^^^^^^^^^^^^^^^^^^^^^^^^^^^^^^^^^^^^
  File "/home/airflow/.local/lib/python3.12/site-packages/airflow/providers/amazon/aws/hooks/s3.py", line 129, in wrapper
    return func(*bound_args.args, **bound_args.kwargs)
           ^^^^^^^^^^^^^^^^^^^^^^^^^^^^^^^^^^^^^^^^^^^
  File "/home/airflow/.local/lib/python3.12/site-packages/airflow/providers/amazon/aws/hooks/s3.py", line 1097, in load_file
    raise ValueError(f"The key {key} already exists.")
ValueError: The key DMMlkp.csv already exists.
[2024-12-02T00:00:04.582+0000] {logging_mixin.py:190} INFO - Task instance in failure state
[2024-12-02T00:00:04.583+0000] {logging_mixin.py:190} INFO - Task start:2024-12-02 00:00:03.524470+00:00 end:2024-12-02 00:00:04.582300+00:00 duration:1.05783
[2024-12-02T00:00:04.584+0000] {logging_mixin.py:190} INFO - Task:<Task(PythonOperator): upload_to_s3> dag:<DAG: s3_dag> dagrun:<DagRun s3_dag @ 2024-12-01 00:00:00+00:00: scheduled__2024-12-01T00:00:00+00:00, state:running, queued_at: 2024-12-02 00:00:00.918753+00:00. externally triggered: False>
[2024-12-02T00:00:04.584+0000] {logging_mixin.py:190} INFO - Failure caused by The key DMMlkp.csv already exists.
[2024-12-02T00:00:04.585+0000] {taskinstance.py:1225} INFO - Marking task as FAILED. dag_id=s3_dag, task_id=upload_to_s3, run_id=scheduled__2024-12-01T00:00:00+00:00, execution_date=20241201T000000, start_date=20241202T000003, end_date=20241202T000004
[2024-12-02T00:00:04.598+0000] {taskinstance.py:340} INFO - ::group::Post task execution logs
[2024-12-02T00:00:04.598+0000] {standard_task_runner.py:124} ERROR - Failed to execute job 200 for task upload_to_s3 (The key DMMlkp.csv already exists.; 9897)
Traceback (most recent call last):
  File "/home/airflow/.local/lib/python3.12/site-packages/airflow/task/task_runner/standard_task_runner.py", line 117, in _start_by_fork
    ret = args.func(args, dag=self.dag)
          ^^^^^^^^^^^^^^^^^^^^^^^^^^^^^
  File "/home/airflow/.local/lib/python3.12/site-packages/airflow/cli/cli_config.py", line 49, in command
    return func(*args, **kwargs)
           ^^^^^^^^^^^^^^^^^^^^^
  File "/home/airflow/.local/lib/python3.12/site-packages/airflow/utils/cli.py", line 116, in wrapper
    return f(*args, **kwargs)
           ^^^^^^^^^^^^^^^^^^
  File "/home/airflow/.local/lib/python3.12/site-packages/airflow/cli/commands/task_command.py", line 483, in task_run
    task_return_code = _run_task_by_selected_method(args, _dag, ti)
                       ^^^^^^^^^^^^^^^^^^^^^^^^^^^^^^^^^^^^^^^^^^^^
  File "/home/airflow/.local/lib/python3.12/site-packages/airflow/cli/commands/task_command.py", line 256, in _run_task_by_selected_method
    return _run_raw_task(args, ti)
           ^^^^^^^^^^^^^^^^^^^^^^^
  File "/home/airflow/.local/lib/python3.12/site-packages/airflow/cli/commands/task_command.py", line 341, in _run_raw_task
    return ti._run_raw_task(
           ^^^^^^^^^^^^^^^^^
  File "/home/airflow/.local/lib/python3.12/site-packages/airflow/utils/session.py", line 97, in wrapper
    return func(*args, session=session, **kwargs)
           ^^^^^^^^^^^^^^^^^^^^^^^^^^^^^^^^^^^^^^
  File "/home/airflow/.local/lib/python3.12/site-packages/airflow/models/taskinstance.py", line 3005, in _run_raw_task
    return _run_raw_task(
           ^^^^^^^^^^^^^^
  File "/home/airflow/.local/lib/python3.12/site-packages/airflow/models/taskinstance.py", line 273, in _run_raw_task
    TaskInstance._execute_task_with_callbacks(
  File "/home/airflow/.local/lib/python3.12/site-packages/airflow/models/taskinstance.py", line 3159, in _execute_task_with_callbacks
    result = self._execute_task(context, task_orig)
             ^^^^^^^^^^^^^^^^^^^^^^^^^^^^^^^^^^^^^^
  File "/home/airflow/.local/lib/python3.12/site-packages/airflow/models/taskinstance.py", line 3183, in _execute_task
    return _execute_task(self, context, task_orig)
           ^^^^^^^^^^^^^^^^^^^^^^^^^^^^^^^^^^^^^^^
  File "/home/airflow/.local/lib/python3.12/site-packages/airflow/models/taskinstance.py", line 767, in _execute_task
    result = _execute_callable(context=context, **execute_callable_kwargs)
             ^^^^^^^^^^^^^^^^^^^^^^^^^^^^^^^^^^^^^^^^^^^^^^^^^^^^^^^^^^^^^
  File "/home/airflow/.local/lib/python3.12/site-packages/airflow/models/taskinstance.py", line 733, in _execute_callable
    return ExecutionCallableRunner(
           ^^^^^^^^^^^^^^^^^^^^^^^^
  File "/home/airflow/.local/lib/python3.12/site-packages/airflow/utils/operator_helpers.py", line 252, in run
    return self.func(*args, **kwargs)
           ^^^^^^^^^^^^^^^^^^^^^^^^^^
  File "/home/airflow/.local/lib/python3.12/site-packages/airflow/models/baseoperator.py", line 417, in wrapper
    return func(self, *args, **kwargs)
           ^^^^^^^^^^^^^^^^^^^^^^^^^^^
  File "/home/airflow/.local/lib/python3.12/site-packages/airflow/operators/python.py", line 238, in execute
    return_value = self.execute_callable()
                   ^^^^^^^^^^^^^^^^^^^^^^^
  File "/home/airflow/.local/lib/python3.12/site-packages/airflow/operators/python.py", line 256, in execute_callable
    return runner.run(*self.op_args, **self.op_kwargs)
           ^^^^^^^^^^^^^^^^^^^^^^^^^^^^^^^^^^^^^^^^^^^
  File "/home/airflow/.local/lib/python3.12/site-packages/airflow/utils/operator_helpers.py", line 252, in run
    return self.func(*args, **kwargs)
           ^^^^^^^^^^^^^^^^^^^^^^^^^^
  File "/opt/airflow/dags/s3_upload.py", line 11, in upload_to_s3
    hook.load_file(filename=filename, key=key, bucket_name=bucket_name)
  File "/home/airflow/.local/lib/python3.12/site-packages/airflow/providers/amazon/aws/hooks/s3.py", line 155, in wrapper
    return func(*bound_args.args, **bound_args.kwargs)
           ^^^^^^^^^^^^^^^^^^^^^^^^^^^^^^^^^^^^^^^^^^^
  File "/home/airflow/.local/lib/python3.12/site-packages/airflow/providers/amazon/aws/hooks/s3.py", line 129, in wrapper
    return func(*bound_args.args, **bound_args.kwargs)
           ^^^^^^^^^^^^^^^^^^^^^^^^^^^^^^^^^^^^^^^^^^^
  File "/home/airflow/.local/lib/python3.12/site-packages/airflow/providers/amazon/aws/hooks/s3.py", line 1097, in load_file
    raise ValueError(f"The key {key} already exists.")
ValueError: The key DMMlkp.csv already exists.
[2024-12-02T00:00:04.654+0000] {local_task_job_runner.py:266} INFO - Task exited with return code 1
[2024-12-02T00:00:04.670+0000] {taskinstance.py:3895} INFO - 0 downstream tasks scheduled from follow-on schedule check
[2024-12-02T00:00:04.673+0000] {local_task_job_runner.py:245} INFO - ::endgroup::
