[2024-11-25T21:47:37.268+0000] {local_task_job_runner.py:123} INFO - ::group::Pre task execution logs
[2024-11-25T21:47:37.285+0000] {taskinstance.py:2613} INFO - Dependencies all met for dep_context=non-requeueable deps ti=<TaskInstance: google_firebase_s3.google_sheet_data_to_s3 manual__2024-11-25T21:42:31.281057+00:00 [queued]>
[2024-11-25T21:47:37.292+0000] {taskinstance.py:2613} INFO - Dependencies all met for dep_context=requeueable deps ti=<TaskInstance: google_firebase_s3.google_sheet_data_to_s3 manual__2024-11-25T21:42:31.281057+00:00 [queued]>
[2024-11-25T21:47:37.294+0000] {taskinstance.py:2866} INFO - Starting attempt 2 of 2
[2024-11-25T21:47:37.308+0000] {taskinstance.py:2889} INFO - Executing <Task(GoogleApiToS3Operator): google_sheet_data_to_s3> on 2024-11-25 21:42:31.281057+00:00
[2024-11-25T21:47:37.314+0000] {warnings.py:112} WARNING - /home/***/.local/lib/python3.12/site-packages/***/task/task_runner/standard_task_runner.py:70: DeprecationWarning: This process (pid=4978) is multi-threaded, use of fork() may lead to deadlocks in the child.
  pid = os.fork()

[2024-11-25T21:47:37.316+0000] {standard_task_runner.py:72} INFO - Started process 4980 to run task
[2024-11-25T21:47:37.317+0000] {standard_task_runner.py:104} INFO - Running: ['***', 'tasks', 'run', 'google_firebase_s3', 'google_sheet_data_to_s3', 'manual__2024-11-25T21:42:31.281057+00:00', '--job-id', '30', '--raw', '--subdir', 'DAGS_FOLDER/google_firebase_s3.py', '--cfg-path', '/tmp/tmp23k72nr9']
[2024-11-25T21:47:37.319+0000] {standard_task_runner.py:105} INFO - Job 30: Subtask google_sheet_data_to_s3
[2024-11-25T21:47:37.367+0000] {task_command.py:467} INFO - Running <TaskInstance: google_firebase_s3.google_sheet_data_to_s3 manual__2024-11-25T21:42:31.281057+00:00 [running]> on host 4b3a7f9b2751
[2024-11-25T21:47:37.456+0000] {taskinstance.py:3132} INFO - Exporting env vars: AIRFLOW_CTX_DAG_OWNER='***' AIRFLOW_CTX_DAG_ID='google_firebase_s3' AIRFLOW_CTX_TASK_ID='google_sheet_data_to_s3' AIRFLOW_CTX_EXECUTION_DATE='2024-11-25T21:42:31.281057+00:00' AIRFLOW_CTX_TRY_NUMBER='2' AIRFLOW_CTX_DAG_RUN_ID='manual__2024-11-25T21:42:31.281057+00:00'
[2024-11-25T21:47:37.458+0000] {logging_mixin.py:190} INFO - Task instance is in running state
[2024-11-25T21:47:37.458+0000] {logging_mixin.py:190} INFO -  Previous state of the Task instance: queued
[2024-11-25T21:47:37.459+0000] {logging_mixin.py:190} INFO - Current task name:google_sheet_data_to_s3 state:running start_date:2024-11-25 21:47:37.285992+00:00
[2024-11-25T21:47:37.460+0000] {logging_mixin.py:190} INFO - Dag name:google_firebase_s3 and current dag run status:running
[2024-11-25T21:47:37.460+0000] {taskinstance.py:731} INFO - ::endgroup::
[2024-11-25T21:47:37.461+0000] {google_api_to_s3.py:142} INFO - Transferring data from sheets to s3
[2024-11-25T21:47:37.479+0000] {taskinstance.py:3311} ERROR - Task failed with exception
Traceback (most recent call last):
  File "/home/airflow/.local/lib/python3.12/site-packages/airflow/models/taskinstance.py", line 767, in _execute_task
    result = _execute_callable(context=context, **execute_callable_kwargs)
             ^^^^^^^^^^^^^^^^^^^^^^^^^^^^^^^^^^^^^^^^^^^^^^^^^^^^^^^^^^^^^
  File "/home/airflow/.local/lib/python3.12/site-packages/airflow/models/taskinstance.py", line 733, in _execute_callable
    return ExecutionCallableRunner(
           ^^^^^^^^^^^^^^^^^^^^^^^^
  File "/home/airflow/.local/lib/python3.12/site-packages/airflow/utils/operator_helpers.py", line 252, in run
    return self.func(*args, **kwargs)
           ^^^^^^^^^^^^^^^^^^^^^^^^^^
  File "/home/airflow/.local/lib/python3.12/site-packages/airflow/models/baseoperator.py", line 417, in wrapper
    return func(self, *args, **kwargs)
           ^^^^^^^^^^^^^^^^^^^^^^^^^^^
  File "/home/airflow/.local/lib/python3.12/site-packages/airflow/providers/amazon/aws/transfers/google_api_to_s3.py", line 147, in execute
    data = self._retrieve_data_from_google_api()
           ^^^^^^^^^^^^^^^^^^^^^^^^^^^^^^^^^^^^^
  File "/home/airflow/.local/lib/python3.12/site-packages/airflow/providers/amazon/aws/transfers/google_api_to_s3.py", line 155, in _retrieve_data_from_google_api
    google_discovery_api_hook = GoogleDiscoveryApiHook(
                                ^^^^^^^^^^^^^^^^^^^^^^^
  File "/home/airflow/.local/lib/python3.12/site-packages/airflow/providers/google/common/hooks/discovery_api.py", line 60, in __init__
    super().__init__(
  File "/home/airflow/.local/lib/python3.12/site-packages/airflow/providers/google/common/hooks/base_google.py", line 289, in __init__
    self.extras: dict = self.get_connection(self.gcp_conn_id).extra_dejson
                        ^^^^^^^^^^^^^^^^^^^^^^^^^^^^^^^^^^^^^
  File "/home/airflow/.local/lib/python3.12/site-packages/airflow/hooks/base.py", line 83, in get_connection
    conn = Connection.get_connection_from_secrets(conn_id)
           ^^^^^^^^^^^^^^^^^^^^^^^^^^^^^^^^^^^^^^^^^^^^^^^
  File "/home/airflow/.local/lib/python3.12/site-packages/airflow/models/connection.py", line 537, in get_connection_from_secrets
    raise AirflowNotFoundException(f"The conn_id `{conn_id}` isn't defined")
airflow.exceptions.AirflowNotFoundException: The conn_id `google_cloud_default` isn't defined
[2024-11-25T21:47:37.485+0000] {logging_mixin.py:190} INFO - Task instance in failure state
[2024-11-25T21:47:37.486+0000] {logging_mixin.py:190} INFO - Task start:2024-11-25 21:47:37.285992+00:00 end:2024-11-25 21:47:37.485077+00:00 duration:0.199085
[2024-11-25T21:47:37.487+0000] {logging_mixin.py:190} INFO - Task:<Task(GoogleApiToS3Operator): google_sheet_data_to_s3> dag:<DAG: google_firebase_s3> dagrun:<DagRun google_firebase_s3 @ 2024-11-25 21:42:31.281057+00:00: manual__2024-11-25T21:42:31.281057+00:00, state:running, queued_at: 2024-11-25 21:42:31.291333+00:00. externally triggered: True>
[2024-11-25T21:47:37.487+0000] {logging_mixin.py:190} INFO - Failure caused by The conn_id `google_cloud_default` isn't defined
[2024-11-25T21:47:37.488+0000] {taskinstance.py:1225} INFO - Marking task as FAILED. dag_id=google_firebase_s3, task_id=google_sheet_data_to_s3, run_id=manual__2024-11-25T21:42:31.281057+00:00, execution_date=20241125T214231, start_date=20241125T214737, end_date=20241125T214737
[2024-11-25T21:47:37.501+0000] {taskinstance.py:340} INFO - ::group::Post task execution logs
[2024-11-25T21:47:37.502+0000] {standard_task_runner.py:124} ERROR - Failed to execute job 30 for task google_sheet_data_to_s3 (The conn_id `google_cloud_default` isn't defined; 4980)
Traceback (most recent call last):
  File "/home/airflow/.local/lib/python3.12/site-packages/airflow/task/task_runner/standard_task_runner.py", line 117, in _start_by_fork
    ret = args.func(args, dag=self.dag)
          ^^^^^^^^^^^^^^^^^^^^^^^^^^^^^
  File "/home/airflow/.local/lib/python3.12/site-packages/airflow/cli/cli_config.py", line 49, in command
    return func(*args, **kwargs)
           ^^^^^^^^^^^^^^^^^^^^^
  File "/home/airflow/.local/lib/python3.12/site-packages/airflow/utils/cli.py", line 116, in wrapper
    return f(*args, **kwargs)
           ^^^^^^^^^^^^^^^^^^
  File "/home/airflow/.local/lib/python3.12/site-packages/airflow/cli/commands/task_command.py", line 483, in task_run
    task_return_code = _run_task_by_selected_method(args, _dag, ti)
                       ^^^^^^^^^^^^^^^^^^^^^^^^^^^^^^^^^^^^^^^^^^^^
  File "/home/airflow/.local/lib/python3.12/site-packages/airflow/cli/commands/task_command.py", line 256, in _run_task_by_selected_method
    return _run_raw_task(args, ti)
           ^^^^^^^^^^^^^^^^^^^^^^^
  File "/home/airflow/.local/lib/python3.12/site-packages/airflow/cli/commands/task_command.py", line 341, in _run_raw_task
    return ti._run_raw_task(
           ^^^^^^^^^^^^^^^^^
  File "/home/airflow/.local/lib/python3.12/site-packages/airflow/utils/session.py", line 97, in wrapper
    return func(*args, session=session, **kwargs)
           ^^^^^^^^^^^^^^^^^^^^^^^^^^^^^^^^^^^^^^
  File "/home/airflow/.local/lib/python3.12/site-packages/airflow/models/taskinstance.py", line 3005, in _run_raw_task
    return _run_raw_task(
           ^^^^^^^^^^^^^^
  File "/home/airflow/.local/lib/python3.12/site-packages/airflow/models/taskinstance.py", line 273, in _run_raw_task
    TaskInstance._execute_task_with_callbacks(
  File "/home/airflow/.local/lib/python3.12/site-packages/airflow/models/taskinstance.py", line 3159, in _execute_task_with_callbacks
    result = self._execute_task(context, task_orig)
             ^^^^^^^^^^^^^^^^^^^^^^^^^^^^^^^^^^^^^^
  File "/home/airflow/.local/lib/python3.12/site-packages/airflow/models/taskinstance.py", line 3183, in _execute_task
    return _execute_task(self, context, task_orig)
           ^^^^^^^^^^^^^^^^^^^^^^^^^^^^^^^^^^^^^^^
  File "/home/airflow/.local/lib/python3.12/site-packages/airflow/models/taskinstance.py", line 767, in _execute_task
    result = _execute_callable(context=context, **execute_callable_kwargs)
             ^^^^^^^^^^^^^^^^^^^^^^^^^^^^^^^^^^^^^^^^^^^^^^^^^^^^^^^^^^^^^
  File "/home/airflow/.local/lib/python3.12/site-packages/airflow/models/taskinstance.py", line 733, in _execute_callable
    return ExecutionCallableRunner(
           ^^^^^^^^^^^^^^^^^^^^^^^^
  File "/home/airflow/.local/lib/python3.12/site-packages/airflow/utils/operator_helpers.py", line 252, in run
    return self.func(*args, **kwargs)
           ^^^^^^^^^^^^^^^^^^^^^^^^^^
  File "/home/airflow/.local/lib/python3.12/site-packages/airflow/models/baseoperator.py", line 417, in wrapper
    return func(self, *args, **kwargs)
           ^^^^^^^^^^^^^^^^^^^^^^^^^^^
  File "/home/airflow/.local/lib/python3.12/site-packages/airflow/providers/amazon/aws/transfers/google_api_to_s3.py", line 147, in execute
    data = self._retrieve_data_from_google_api()
           ^^^^^^^^^^^^^^^^^^^^^^^^^^^^^^^^^^^^^
  File "/home/airflow/.local/lib/python3.12/site-packages/airflow/providers/amazon/aws/transfers/google_api_to_s3.py", line 155, in _retrieve_data_from_google_api
    google_discovery_api_hook = GoogleDiscoveryApiHook(
                                ^^^^^^^^^^^^^^^^^^^^^^^
  File "/home/airflow/.local/lib/python3.12/site-packages/airflow/providers/google/common/hooks/discovery_api.py", line 60, in __init__
    super().__init__(
  File "/home/airflow/.local/lib/python3.12/site-packages/airflow/providers/google/common/hooks/base_google.py", line 289, in __init__
    self.extras: dict = self.get_connection(self.gcp_conn_id).extra_dejson
                        ^^^^^^^^^^^^^^^^^^^^^^^^^^^^^^^^^^^^^
  File "/home/airflow/.local/lib/python3.12/site-packages/airflow/hooks/base.py", line 83, in get_connection
    conn = Connection.get_connection_from_secrets(conn_id)
           ^^^^^^^^^^^^^^^^^^^^^^^^^^^^^^^^^^^^^^^^^^^^^^^
  File "/home/airflow/.local/lib/python3.12/site-packages/airflow/models/connection.py", line 537, in get_connection_from_secrets
    raise AirflowNotFoundException(f"The conn_id `{conn_id}` isn't defined")
airflow.exceptions.AirflowNotFoundException: The conn_id `google_cloud_default` isn't defined
[2024-11-25T21:47:37.532+0000] {local_task_job_runner.py:266} INFO - Task exited with return code 1
[2024-11-25T21:47:37.548+0000] {taskinstance.py:3895} INFO - 0 downstream tasks scheduled from follow-on schedule check
[2024-11-25T21:47:37.551+0000] {local_task_job_runner.py:245} INFO - ::endgroup::
